<?xml version="1.0" encoding="UTF-8"?>
<testng-results skipped="0" failed="1" total="1" passed="0">
  <reporter-output>
  </reporter-output>
  <suite name="Default suite" duration-ms="15295" started-at="2019-04-30T13:13:20Z" finished-at="2019-04-30T13:13:36Z">
    <groups>
    </groups>
    <test name="Default test" duration-ms="15295" started-at="2019-04-30T13:13:20Z" finished-at="2019-04-30T13:13:36Z">
      <class name="com.qa.test.Signin_Page_Test">
        <test-method status="PASS" signature="setup()[pri:0, instance:com.qa.test.Signin_Page_Test@26be92ad]" name="setup" is-config="true" duration-ms="13532" started-at="2019-04-30T18:43:20Z" finished-at="2019-04-30T18:43:34Z">
          <reporter-output>
          </reporter-output>
        </test-method> <!-- setup -->
        <test-method status="FAIL" signature="validate_signin(java.lang.String, java.lang.String)[pri:0, instance:com.qa.test.Signin_Page_Test@26be92ad]" name="validate_signin" duration-ms="0" started-at="2019-04-30T18:43:35Z" data-provider="get_Signin_Data" finished-at="2019-04-30T18:43:35Z">
          <exception class="java.lang.RuntimeException">
            <message>
              <![CDATA[java.lang.NullPointerException]]>
            </message>
            <full-stacktrace>
              <![CDATA[java.lang.RuntimeException: java.lang.NullPointerException
	at org.testng.internal.MethodInvocationHelper.invokeDataProvider(MethodInvocationHelper.java:143)
	at org.testng.internal.Parameters.handleParameters(Parameters.java:426)
	at org.testng.internal.Invoker.handleParameters(Invoker.java:1383)
	at org.testng.internal.Invoker.createParameters(Invoker.java:1075)
	at org.testng.internal.Invoker.invokeTestMethods(Invoker.java:1180)
	at org.testng.internal.TestMethodWorker.invokeTestMethods(TestMethodWorker.java:127)
	at org.testng.internal.TestMethodWorker.run(TestMethodWorker.java:111)
	at org.testng.TestRunner.privateRun(TestRunner.java:767)
	at org.testng.TestRunner.run(TestRunner.java:617)
	at org.testng.SuiteRunner.runTest(SuiteRunner.java:334)
	at org.testng.SuiteRunner.runSequentially(SuiteRunner.java:329)
	at org.testng.SuiteRunner.privateRun(SuiteRunner.java:291)
	at org.testng.SuiteRunner.run(SuiteRunner.java:240)
	at org.testng.SuiteRunnerWorker.runSuite(SuiteRunnerWorker.java:52)
	at org.testng.SuiteRunnerWorker.run(SuiteRunnerWorker.java:86)
	at org.testng.TestNG.runSuitesSequentially(TestNG.java:1198)
	at org.testng.TestNG.runSuitesLocally(TestNG.java:1123)
	at org.testng.TestNG.run(TestNG.java:1031)
	at org.testng.remote.AbstractRemoteTestNG.run(AbstractRemoteTestNG.java:115)
	at org.testng.remote.RemoteTestNG.initAndRun(RemoteTestNG.java:251)
	at org.testng.remote.RemoteTestNG.main(RemoteTestNG.java:77)
Caused by: java.lang.NullPointerException
	at com.qa.util.TestData_Excel.getTestData(TestData_Excel.java:40)
	at com.qa.test.Signin_Page_Test.get_Signin_Data(Signin_Page_Test.java:33)
	at sun.reflect.NativeMethodAccessorImpl.invoke0(Native Method)
	at sun.reflect.NativeMethodAccessorImpl.invoke(Unknown Source)
	at sun.reflect.DelegatingMethodAccessorImpl.invoke(Unknown Source)
	at java.lang.reflect.Method.invoke(Unknown Source)
	at org.testng.internal.MethodInvocationHelper.invokeMethod(MethodInvocationHelper.java:80)
	at org.testng.internal.MethodInvocationHelper.invokeDataProvider(MethodInvocationHelper.java:117)
	... 20 more
]]>
            </full-stacktrace>
          </exception> <!-- java.lang.RuntimeException -->
          <reporter-output>
          </reporter-output>
        </test-method> <!-- validate_signin -->
        <test-method status="PASS" signature="exit()[pri:0, instance:com.qa.test.Signin_Page_Test@26be92ad]" name="exit" is-config="true" duration-ms="795" started-at="2019-04-30T18:43:35Z" finished-at="2019-04-30T18:43:36Z">
          <reporter-output>
          </reporter-output>
        </test-method> <!-- exit -->
      </class> <!-- com.qa.test.Signin_Page_Test -->
    </test> <!-- Default test -->
  </suite> <!-- Default suite -->
</testng-results>
